Workbook

Sheet Dashboard
B1: SALES CRM — DAILY CONTROL DASHBOARD
B2: GREEN ENERGY ROLF LUBRICANTS TRADING L.L.C · choose the report date and manager in the yellow cells; everything below recalculates.
B4: Report date | C4: =TODAY() -> 46297 | F4: Tip: type a past date to review any previous day.
B5: Sales manager | C5: All | Z5: =IF(C5="All","<>§",C5) -> <>§
B7: TODAY AT A GLANCE (for the report date & manager selected above)
B9: Activities logged | D9: New leads added | F9: Follow-ups due | H9: Overdue follow-ups | J9: How to read:
B10: =COUNTIFS('Activity Log'!$A$5:$A$3004,RptDate,'Activity Log'!$B$5:$B$3004,MgrCrit) -> 0 | D10: =COUNTIFS('Leads Pipeline'!$B$5:$B$1004,RptDate,'Leads Pipeline'!$C$5:$C$1004,MgrCrit,'Leads Pipeline'!$F$5:$F$1004,"<>") -> 0 | F10: =COUNTIFS('Leads Pipeline'!$S$5:$S$1004,RptDate,'Leads Pipeline'!$O$5:$O$1004,"<>Won",'Leads Pipeline'!$O$5:$O$1004,"<>Lost",'Leads Pipeline'!$F$5:$F$1004,"<>",'Leads Pipeline'!$C$5:$C$1004,MgrCrit)+COUNTIFS('Active Clients'!$U$5:$U$504,RptDate,'Active Clients'!$K$5:$K$504,MgrCrit,'Active Clients'!$D$5:$D$504,"<>") -> 0 | H10: =COUNTIFS('Leads Pipeline'!$S$5:$S$1004,"<"&RptDate,'Leads Pipeline'!$O$5:$O$1004,"<>Won",'Leads Pipeline'!$O$5:$O$1004,"<>Lost",'Leads Pipeline'!$F$5:$F$1004,"<>",'Leads Pipeline'!$C$5:$C$1004,MgrCrit)+COUNTIFS('Active Clients'!$U$5:$U$504,"<"&RptDate,'Active Clients'!$K$5:$K$504,MgrCrit,'Active Clients'!$D$5:$D$504,"<>") -> 0 | J10: Overdue = next action date has passed and the lead is still open (or client follow-up missed).
B12: Open leads | D12: Open pipeline (USD) | F12: Active clients | H12: Sales YTD (USD)
B13: =COUNTIFS('Leads Pipeline'!$O$5:$O$1004,"<>Won",'Leads Pipeline'!$O$5:$O$1004,"<>Lost",'Leads Pipeline'!$F$5:$F$1004,"<>",'Leads Pipeline'!$C$5:$C$1004,MgrCrit) -> 1 | D13: =SUMIFS('Leads Pipeline'!$U$5:$U$1004,'Leads Pipeline'!$O$5:$O$1004,"<>Won",'Leads Pipeline'!$O$5:$O$1004,"<>Lost",'Leads Pipeline'!$C$5:$C$1004,MgrCrit) -> 25000 | F13: =COUNTIFS('Active Clients'!$T$5:$T$504,"Active",'Active Clients'!$K$5:$K$504,MgrCrit) -> 1 | H13: =SUMIFS('Active Clients'!$R$5:$R$504,'Active Clients'!$K$5:$K$504,MgrCrit) -> 64000
B16: ACTIVITY ON REPORT DATE (by type) | G16: LAST 7 DAYS (activity per day)
B17: Activity type | C17: Count | D17: Positive outcome | G17: Date | H17: Day | I17: Activities | J17: New leads
B18: =Lists!G5 -> Call | C18: =IF(B18="","",COUNTIFS('Activity Log'!$A$5:$A$3004,RptDate,'Activity Log'!$G$5:$G$3004,B18,'Activity Log'!$B$5:$B$3004,MgrCrit)) -> 0 | D18: =IF(B18="","",COUNTIFS('Activity Log'!$A$5:$A$3004,RptDate,'Activity Log'!$G$5:$G$3004,B18,'Activity Log'!$I$5:$I$3004,"Positive",'Activity Log'!$B$5:$B$3004,MgrCrit)) -> 0 | G18: =RptDate-6 -> 46291 | H18: =TEXT(G18,"ddd") -> Sat | I18: =COUNTIFS('Activity Log'!$A$5:$A$3004,G18,'Activity Log'!$B$5:$B$3004,MgrCrit) -> 0 | J18: =COUNTIFS('Leads Pipeline'!$B$5:$B$1004,G18,'Leads Pipeline'!$C$5:$C$1004,MgrCrit,'Leads Pipeline'!$F$5:$F$1004,"<>") -> 0
B19: =Lists!G6 -> WhatsApp | C19: =IF(B19="","",COUNTIFS('Activity Log'!$A$5:$A$3004,RptDate,'Activity Log'!$G$5:$G$3004,B19,'Activity Log'!$B$5:$B$3004,MgrCrit)) -> 0 | D19: =IF(B19="","",COUNTIFS('Activity Log'!$A$5:$A$3004,RptDate,'Activity Log'!$G$5:$G$3004,B19,'Activity Log'!$I$5:$I$3004,"Positive",'Activity Log'!$B$5:$B$3004,MgrCrit)) -> 0 | G19: =RptDate-5 -> 46292 | H19: =TEXT(G19,"ddd") -> Sun | I19: =COUNTIFS('Activity Log'!$A$5:$A$3004,G19,'Activity Log'!$B$5:$B$3004,MgrCrit) -> 0 | J19: =COUNTIFS('Leads Pipeline'!$B$5:$B$1004,G19,'Leads Pipeline'!$C$5:$C$1004,MgrCrit,'Leads Pipeline'!$F$5:$F$1004,"<>") -> 0
B20: =Lists!G7 -> Email | C20: =IF(B20="","",COUNTIFS('Activity Log'!$A$5:$A$3004,RptDate,'Activity Log'!$G$5:$G$3004,B20,'Activity Log'!$B$5:$B$3004,MgrCrit)) -> 0 | D20: =IF(B20="","",COUNTIFS('Activity Log'!$A$5:$A$3004,RptDate,'Activity Log'!$G$5:$G$3004,B20,'Activity Log'!$I$5:$I$3004,"Positive",'Activity Log'!$B$5:$B$3004,MgrCrit)) -> 0 | G20: =RptDate-4 -> 46293 | H20: =TEXT(G20,"ddd") -> Mon | I20: =COUNTIFS('Activity Log'!$A$5:$A$3004,G20,'Activity Log'!$B$5:$B$3004,MgrCrit) -> 0 | J20: =COUNTIFS('Leads Pipeline'!$B$5:$B$1004,G20,'Leads Pipeline'!$C$5:$C$1004,MgrCrit,'Leads Pipeline'!$F$5:$F$1004,"<>") -> 1
B21: =Lists!G8 -> Meeting | C21: =IF(B21="","",COUNTIFS('Activity Log'!$A$5:$A$3004,RptDate,'Activity Log'!$G$5:$G$3004,B21,'Activity Log'!$B$5:$B$3004,MgrCrit)) -> 0 | D21: =IF(B21="","",COUNTIFS('Activity Log'!$A$5:$A$3004,RptDate,'Activity Log'!$G$5:$G$3004,B21,'Activity Log'!$I$5:$I$3004,"Positive",'Activity Log'!$B$5:$B$3004,MgrCrit)) -> 0 | G21: =RptDate-3 -> 46294 | H21: =TEXT(G21,"ddd") -> Tue | I21: =COUNTIFS('Activity Log'!$A$5:$A$3004,G21,'Activity Log'!$B$5:$B$3004,MgrCrit) -> 0 | J21: =COUNTIFS('Leads Pipeline'!$B$5:$B$1004,G21,'Leads Pipeline'!$C$5:$C$1004,MgrCrit,'Leads Pipeline'!$F$5:$F$1004,"<>") -> 0
B22: =Lists!G9 -> Visit | C22: =IF(B22="","",COUNTIFS('Activity Log'!$A$5:$A$3004,RptDate,'Activity Log'!$G$5:$G$3004,B22,'Activity Log'!$B$5:$B$3004,MgrCrit)) -> 0 | D22: =IF(B22="","",COUNTIFS('Activity Log'!$A$5:$A$3004,RptDate,'Activity Log'!$G$5:$G$3004,B22,'Activity Log'!$I$5:$I$3004,"Positive",'Activity Log'!$B$5:$B$3004,MgrCrit)) -> 0 | G22: =RptDate-2 -> 46295 | H22: =TEXT(G22,"ddd") -> Wed | I22: =COUNTIFS('Activity Log'!$A$5:$A$3004,G22,'Activity Log'!$B$5:$B$3004,MgrCrit) -> 0 | J22: =COUNTIFS('Leads Pipeline'!$B$5:$B$1004,G22,'Leads Pipeline'!$C$5:$C$1004,MgrCrit,'Leads Pipeline'!$F$5:$F$1004,"<>") -> 0
B23: =Lists!G10 -> Offer sent | C23: =IF(B23="","",COUNTIFS('Activity Log'!$A$5:$A$3004,RptDate,'Activity Log'!$G$5:$G$3004,B23,'Activity Log'!$B$5:$B$3004,MgrCrit)) -> 0 | D23: =IF(B23="","",COUNTIFS('Activity Log'!$A$5:$A$3004,RptDate,'Activity Log'!$G$5:$G$3004,B23,'Activity Log'!$I$5:$I$3004,"Positive",'Activity Log'!$B$5:$B$3004,MgrCrit)) -> 0 | G23: =RptDate-1 -> 46296 | H23: =TEXT(G23,"ddd") -> Thu | I23: =COUNTIFS('Activity Log'!$A$5:$A$3004,G23,'Activity Log'!$B$5:$B$3004,MgrCrit) -> 1 | J23: =COUNTIFS('Leads Pipeline'!$B$5:$B$1004,G23,'Leads Pipeline'!$C$5:$C$1004,MgrCrit,'Leads Pipeline'!$F$5:$F$1004,"<>") -> 0
B24: =Lists!G11 -> Samples sent | C24: =IF(B24="","",COUNTIFS('Activity Log'!$A$5:$A$3004,RptDate,'Activity Log'!$G$5:$G$3004,B24,'Activity Log'!$B$5:$B$3004,MgrCrit)) -> 0 | D24: =IF(B24="","",COUNTIFS('Activity Log'!$A$5:$A$3004,RptDate,'Activity Log'!$G$5:$G$3004,B24,'Activity Log'!$I$5:$I$3004,"Positive",'Activity Log'!$B$5:$B$3004,MgrCrit)) -> 0 | G24: =RptDate-0 -> 46297 | H24: =TEXT(G24,"ddd") -> Fri | I24: =COUNTIFS('Activity Log'!$A$5:$A$3004,G24,'Activity Log'!$B$5:$B$3004,MgrCrit) -> 0 | J24: =COUNTIFS('Leads Pipeline'!$B$5:$B$1004,G24,'Leads Pipeline'!$C$5:$C$1004,MgrCrit,'Leads Pipeline'!$F$5:$F$1004,"<>") -> 0
B25: =Lists!G12 -> Order received | C25: =IF(B25="","",COUNTIFS('Activity Log'!$A$5:$A$3004,RptDate,'Activity Log'!$G$5:$G$3004,B25,'Activity Log'!$B$5:$B$3004,MgrCrit)) -> 0 | D25: =IF(B25="","",COUNTIFS('Activity Log'!$A$5:$A$3004,RptDate,'Activity Log'!$G$5:$G$3004,B25,'Activity Log'!$I$5:$I$3004,"Positive",'Activity Log'!$B$5:$B$3004,MgrCrit)) -> 0 | G25: 7-day total | I25: =SUM(I18:I24) -> 1 | J25: =SUM(J18:J24) -> 1
B26: =Lists!G13 -> Payment follow-up | C26: =IF(B26="","",COUNTIFS('Activity Log'!$A$5:$A$3004,RptDate,'Activity Log'!$G$5:$G$3004,B26,'Activity Log'!$B$5:$B$3004,MgrCrit)) -> 0 | D26: =IF(B26="","",COUNTIFS('Activity Log'!$A$5:$A$3004,RptDate,'Activity Log'!$G$5:$G$3004,B26,'Activity Log'!$I$5:$I$3004,"Positive",'Activity Log'!$B$5:$B$3004,MgrCrit)) -> 0 | G26: Red = working day with no activity logged
B27: =Lists!G14 -> Other | C27: =IF(B27="","",COUNTIFS('Activity Log'!$A$5:$A$3004,RptDate,'Activity Log'!$G$5:$G$3004,B27,'Activity Log'!$B$5:$B$3004,MgrCrit)) -> 0 | D27: =IF(B27="","",COUNTIFS('Activity Log'!$A$5:$A$3004,RptDate,'Activity Log'!$G$5:$G$3004,B27,'Activity Log'!$I$5:$I$3004,"Positive",'Activity Log'!$B$5:$B$3004,MgrCrit)) -> 0
B28: Total | C28: =SUM(C18:C27) -> 0 | D28: =SUM(D18:D27) -> 0
B30: PIPELINE BY STATUS
B31: Status | C31: Leads | D31: Deal value (USD) | E31: Volume (L/month)
B32: =Lists!D5 -> New | C32: =IF(B32="","",COUNTIFS('Leads Pipeline'!$O$5:$O$1004,B32,'Leads Pipeline'!$C$5:$C$1004,MgrCrit)) -> 0 | D32: =IF(B32="","",SUMIFS('Leads Pipeline'!$U$5:$U$1004,'Leads Pipeline'!$O$5:$O$1004,B32,'Leads Pipeline'!$C$5:$C$1004,MgrCrit)) -> 0 | E32: =IF(B32="","",SUMIFS('Leads Pipeline'!$T$5:$T$1004,'Leads Pipeline'!$O$5:$O$1004,B32,'Leads Pipeline'!$C$5:$C$1004,MgrCrit)) -> 0
B33: =Lists!D6 -> Contacted | C33: =IF(B33="","",COUNTIFS('Leads Pipeline'!$O$5:$O$1004,B33,'Leads Pipeline'!$C$5:$C$1004,MgrCrit)) -> 0 | D33: =IF(B33="","",SUMIFS('Leads Pipeline'!$U$5:$U$1004,'Leads Pipeline'!$O$5:$O$1004,B33,'Leads Pipeline'!$C$5:$C$1004,MgrCrit)) -> 0 | E33: =IF(B33="","",SUMIFS('Leads Pipeline'!$T$5:$T$1004,'Leads Pipeline'!$O$5:$O$1004,B33,'Leads Pipeline'!$C$5:$C$1004,MgrCrit)) -> 0
B34: =Lists!D7 -> Interested | C34: =IF(B34="","",COUNTIFS('Leads Pipeline'!$O$5:$O$1004,B34,'Leads Pipeline'!$C$5:$C$1004,MgrCrit)) -> 0 | D34: =IF(B34="","",SUMIFS('Leads Pipeline'!$U$5:$U$1004,'Leads Pipeline'!$O$5:$O$1004,B34,'Leads Pipeline'!$C$5:$C$1004,MgrCrit)) -> 0 | E34: =IF(B34="","",SUMIFS('Leads Pipeline'!$T$5:$T$1004,'Leads Pipeline'!$O$5:$O$1004,B34,'Leads Pipeline'!$C$5:$C$1004,MgrCrit)) -> 0
B35: =Lists!D8 -> Samples Sent | C35: =IF(B35="","",COUNTIFS('Leads Pipeline'!$O$5:$O$1004,B35,'Leads Pipeline'!$C$5:$C$1004,MgrCrit)) -> 1 | D35: =IF(B35="","",SUMIFS('Leads Pipeline'!$U$5:$U$1004,'Leads Pipeline'!$O$5:$O$1004,B35,'Leads Pipeline'!$C$5:$C$1004,MgrCrit)) -> 25000 | E35: =IF(B35="","",SUMIFS('Leads Pipeline'!$T$5:$T$1004,'Leads Pipeline'!$O$5:$O$1004,B35,'Leads Pipeline'!$C$5:$C$1004,MgrCrit)) -> 5000
B36: =Lists!D9 -> Offer Sent | C36: =IF(B36="","",COUNTIFS('Leads Pipeline'!$O$5:$O$1004,B36,'Leads Pipeline'!$C$5:$C$1004,MgrCrit)) -> 0 | D36: =IF(B36="","",SUMIFS('Leads Pipeline'!$U$5:$U$1004,'Leads Pipeline'!$O$5:$O$1004,B36,'Leads Pipeline'!$C$5:$C$1004,MgrCrit)) -> 0 | E36: =IF(B36="","",SUMIFS('Leads Pipeline'!$T$5:$T$1004,'Leads Pipeline'!$O$5:$O$1004,B36,'Leads Pipeline'!$C$5:$C$1004,MgrCrit)) -> 0
B37: =Lists!D10 -> Negotiation | C37: =IF(B37="","",COUNTIFS('Leads Pipeline'!$O$5:$O$1004,B37,'Leads Pipeline'!$C$5:$C$1004,MgrCrit)) -> 0 | D37: =IF(B37="","",SUMIFS('Leads Pipeline'!$U$5:$U$1004,'Leads Pipeline'!$O$5:$O$1004,B37,'Leads Pipeline'!$C$5:$C$1004,MgrCrit)) -> 0 | E37: =IF(B37="","",SUMIFS('Leads Pipeline'!$T$5:$T$1004,'Leads Pipeline'!$O$5:$O$1004,B37,'Leads Pipeline'!$C$5:$C$1004,MgrCrit)) -> 0
B38: =Lists!D11 -> Won | C38: =IF(B38="","",COUNTIFS('Leads Pipeline'!$O$5:$O$1004,B38,'Leads Pipeline'!$C$5:$C$1004,MgrCrit)) -> 0 | D38: =IF(B38="","",SUMIFS('Leads Pipeline'!$U$5:$U$1004,'Leads Pipeline'!$O$5:$O$1004,B38,'Leads Pipeline'!$C$5:$C$1004,MgrCrit)) -> 0 | E38: =IF(B38="","",SUMIFS('Leads Pipeline'!$T$5:$T$1004,'Leads Pipeline'!$O$5:$O$1004,B38,'Leads Pipeline'!$C$5:$C$1004,MgrCrit)) -> 0
B39: =Lists!D12 -> Lost | C39: =IF(B39="","",COUNTIFS('Leads Pipeline'!$O$5:$O$1004,B39,'Leads Pipeline'!$C$5:$C$1004,MgrCrit)) -> 0 | D39: =IF(B39="","",SUMIFS('Leads Pipeline'!$U$5:$U$1004,'Leads Pipeline'!$O$5:$O$1004,B39,'Leads Pipeline'!$C$5:$C$1004,MgrCrit)) -> 0 | E39: =IF(B39="","",SUMIFS('Leads Pipeline'!$T$5:$T$1004,'Leads Pipeline'!$O$5:$O$1004,B39,'Leads Pipeline'!$C$5:$C$1004,MgrCrit)) -> 0
B40: =Lists!D13 -> On Hold | C40: =IF(B40="","",COUNTIFS('Leads Pipeline'!$O$5:$O$1004,B40,'Leads Pipeline'!$C$5:$C$1004,MgrCrit)) -> 0 | D40: =IF(B40="","",SUMIFS('Leads Pipeline'!$U$5:$U$1004,'Leads Pipeline'!$O$5:$O$1004,B40,'Leads Pipeline'!$C$5:$C$1004,MgrCrit)) -> 0 | E40: =IF(B40="","",SUMIFS('Leads Pipeline'!$T$5:$T$1004,'Leads Pipeline'!$O$5:$O$1004,B40,'Leads Pipeline'!$C$5:$C$1004,MgrCrit)) -> 0
B42: BY COUNTRY
B43: Country | C43: Total leads | D43: Open leads | E43: Hot leads | F43: Offer / Negotiation | G43: Won | H43: Lost | I43: Open pipeline (USD) | J43: Active clients | K43: Sales YTD (USD) | L43: Activities (7 days)
B44: =IF(Lists!B5="","",Lists!B5) -> United Arab Emirates | C44: =IF($B44="","",COUNTIFS('Leads Pipeline'!$D$5:$D$1004,$B44,'Leads Pipeline'!$F$5:$F$1004,"<>",'Leads Pipeline'!$C$5:$C$1004,MgrCrit)) -> 0 | D44: =IF($B44="","",COUNTIFS('Leads Pipeline'!$D$5:$D$1004,$B44,'Leads Pipeline'!$O$5:$O$1004,"<>Won",'Leads Pipeline'!$O$5:$O$1004,"<>Lost",'Leads Pipeline'!$F$5:$F$1004,"<>",'Leads Pipeline'!$C$5:$C$1004,MgrCrit)) -> 0 | E44: =IF($B44="","",COUNTIFS('Leads Pipeline'!$D$5:$D$1004,$B44,'Leads Pipeline'!$P$5:$P$1004,"Hot",'Leads Pipeline'!$O$5:$O$1004,"<>Won",'Leads Pipeline'!$O$5:$O$1004,"<>Lost",'Leads Pipeline'!$F$5:$F$1004,"<>",'Leads Pipeline'!$C$5:$C$1004,MgrCrit)) -> 0 | F44: =IF($B44="","",COUNTIFS('Leads Pipeline'!$D$5:$D$1004,$B44,'Leads Pipeline'!$O$5:$O$1004,"Offer Sent",'Leads Pipeline'!$C$5:$C$1004,MgrCrit)+COUNTIFS('Leads Pipeline'!$D$5:$D$1004,$B44,'Leads Pipeline'!$O$5:$O$1004,"Negotiation",'Leads Pipeline'!$C$5:$C$1004,MgrCrit)) -> 0 | G44: =IF($B44="","",COUNTIFS('Leads Pipeline'!$D$5:$D$1004,$B44,'Leads Pipeline'!$O$5:$O$1004,"Won",'Leads Pipeline'!$C$5:$C$1004,MgrCrit)) -> 0 | H44: =IF($B44="","",COUNTIFS('Leads Pipeline'!$D$5:$D$1004,$B44,'Leads Pipeline'!$O$5:$O$1004,"Lost",'Leads Pipeline'!$C$5:$C$1004,MgrCrit)) -> 0 | I44: =IF($B44="","",SUMIFS('Leads Pipeline'!$U$5:$U$1004,'Leads Pipeline'!$D$5:$D$1004,$B44,'Leads Pipeline'!$O$5:$O$1004,"<>Won",'Leads Pipeline'!$O$5:$O$1004,"<>Lost",'Leads Pipeline'!$C$5:$C$1004,MgrCrit)) -> 0 | J44: =IF($B44="","",COUNTIFS('Active Clients'!$B$5:$B$504,$B44,'Active Clients'!$T$5:$T$504,"Active",'Active Clients'!$K$5:$K$504,MgrCrit)) -> 1 | K44: =IF($B44="","",SUMIFS('Active Clients'!$R$5:$R$504,'Active Clients'!$B$5:$B$504,$B44,'Active Clients'!$K$5:$K$504,MgrCrit)) -> 64000 | L44: =IF($B44="","",COUNTIFS('Activity Log'!$E$5:$E$3004,$B44,'Activity Log'!$A$5:$A$3004,">="&(RptDate-6),'Activity Log'!$A$5:$A$3004,"<="&RptDate,'Activity Log'!$B$5:$B$3004,MgrCrit)) -> 0
B45: =IF(Lists!B6="","",Lists!B6) -> Saudi Arabia | C45: =IF($B45="","",COUNTIFS('Leads Pipeline'!$D$5:$D$1004,$B45,'Leads Pipeline'!$F$5:$F$1004,"<>",'Leads Pipeline'!$C$5:$C$1004,MgrCrit)) -> 1 | D45: =IF($B45="","",COUNTIFS('Leads Pipeline'!$D$5:$D$1004,$B45,'Leads Pipeline'!$O$5:$O$1004,"<>Won",'Leads Pipeline'!$O$5:$O$1004,"<>Lost",'Leads Pipeline'!$F$5:$F$1004,"<>",'Leads Pipeline'!$C$5:$C$1004,MgrCrit)) -> 1 | E45: =IF($B45="","",COUNTIFS('Leads Pipeline'!$D$5:$D$1004,$B45,'Leads Pipeline'!$P$5:$P$1004,"Hot",'Leads Pipeline'!$O$5:$O$1004,"<>Won",'Leads Pipeline'!$O$5:$O$1004,"<>Lost",'Leads Pipeline'!$F$5:$F$1004,"<>",'Leads Pipeline'!$C$5:$C$1004,MgrCrit)) -> 1 | F45: =IF($B45="","",COUNTIFS('Leads Pipeline'!$D$5:$D$1004,$B45,'Leads Pipeline'!$O$5:$O$1004,"Offer Sent",'Leads Pipeline'!$C$5:$C$1004,MgrCrit)+COUNTIFS('Leads Pipeline'!$D$5:$D$1004,$B45,'Leads Pipeline'!$O$5:$O$1004,"Negotiation",'Leads Pipeline'!$C$5:$C$1004,MgrCrit)) -> 0 | G45: =IF($B45="","",COUNTIFS('Leads Pipeline'!$D$5:$D$1004,$B45,'Leads Pipeline'!$O$5:$O$1004,"Won",'Leads Pipeline'!$C$5:$C$1004,MgrCrit)) -> 0 | H45: =IF($B45="","",COUNTIFS('Leads Pipeline'!$D$5:$D$1004,$B45,'Leads Pipeline'!$O$5:$O$1004,"Lost",'Leads Pipeline'!$C$5:$C$1004,MgrCrit)) -> 0 | I45: =IF($B45="","",SUMIFS('Leads Pipeline'!$U$5:$U$1004,'Leads Pipeline'!$D$5:$D$1004,$B45,'Leads Pipeline'!$O$5:$O$1004,"<>Won",'Leads Pipeline'!$O$5:$O$1004,"<>Lost",'Leads Pipeline'!$C$5:$C$1004,MgrCrit)) -> 25000 | J45: =IF($B45="","",COUNTIFS('Active Clients'!$B$5:$B$504,$B45,'Active Clients'!$T$5:$T$504,"Active",'Active Clients'!$K$5:$K$504,MgrCrit)) -> 0 | K45: =IF($B45="","",SUMIFS('Active Clients'!$R$5:$R$504,'Active Clients'!$B$5:$B$504,$B45,'Active Clients'!$K$5:$K$504,MgrCrit)) -> 0 | L45: =IF($B45="","",COUNTIFS('Activity Log'!$E$5:$E$3004,$B45,'Activity Log'!$A$5:$A$3004,">="&(RptDate-6),'Activity Log'!$A$5:$A$3004,"<="&RptDate,'Activity Log'!$B$5:$B$3004,MgrCrit)) -> 1
B46: =IF(Lists!B7="","",Lists!B7) -> Oman | C46: =IF($B46="","",COUNTIFS('Leads Pipeline'!$D$5:$D$1004,$B46,'Leads Pipeline'!$F$5:$F$1004,"<>",'Leads Pipeline'!$C$5:$C$1004,MgrCrit)) -> 0 | D46: =IF($B46="","",COUNTIFS('Leads Pipeline'!$D$5:$D$1004,$B46,'Leads Pipeline'!$O$5:$O$1004,"<>Won",'Leads Pipeline'!$O$5:$O$1004,"<>Lost",'Leads Pipeline'!$F$5:$F$1004,"<>",'Leads Pipeline'!$C$5:$C$1004,MgrCrit)) -> 0 | E46: =IF($B46="","",COUNTIFS('Leads Pipeline'!$D$5:$D$1004,$B46,'Leads Pipeline'!$P$5:$P$1004,"Hot",'Leads Pipeline'!$O$5:$O$1004,"<>Won",'Leads Pipeline'!$O$5:$O$1004,"<>Lost",'Leads Pipeline'!$F$5:$F$1004,"<>",'Leads Pipeline'!$C$5:$C$1004,MgrCrit)) -> 0 | F46: =IF($B46="","",COUNTIFS('Leads Pipeline'!$D$5:$D$1004,$B46,'Leads Pipeline'!$O$5:$O$1004,"Offer Sent",'Leads Pipeline'!$C$5:$C$1004,MgrCrit)+COUNTIFS('Leads Pipeline'!$D$5:$D$1004,$B46,'Leads Pipeline'!$O$5:$O$1004,"Negotiation",'Leads Pipeline'!$C$5:$C$1004,MgrCrit)) -> 0 | G46: =IF($B46="","",COUNTIFS('Leads Pipeline'!$D$5:$D$1004,$B46,'Leads Pipeline'!$O$5:$O$1004,"Won",'Leads Pipeline'!$C$5:$C$1004,MgrCrit)) -> 0 | H46: =IF($B46="","",COUNTIFS('Leads Pipeline'!$D$5:$D$1004,$B46,'Leads Pipeline'!$O$5:$O$1004,"Lost",'Leads Pipeline'!$C$5:$C$1004,MgrCrit)) -> 0 | I46: =IF($B46="","",SUMIFS('Leads Pipeline'!$U$5:$U$1004,'Leads Pipeline'!$D$5:$D$1004,$B46,'Leads Pipeline'!$O$5:$O$1004,"<>Won",'Leads Pipeline'!$O$5:$O$1004,"<>Lost",'Leads Pipeline'!$C$5:$C$1004,MgrCrit)) -> 0 | J46: =IF($B46="","",COUNTIFS('Active Clients'!$B$5:$B$504,$B46,'Active Clients'!$T$5:$T$504,"Active",'Active Clients'!$K$5:$K$504,MgrCrit)) -> 0 | K46: =IF($B46="","",SUMIFS('Active Clients'!$R$5:$R$504,'Active Clients'!$B$5:$B$504,$B46,'Active Clients'!$K$5:$K$504,MgrCrit)) -> 0 | L46: =IF($B46="","",COUNTIFS('Activity Log'!$E$5:$E$3004,$B46,'Activity Log'!$A$5:$A$3004,">="&(RptDate-6),'Activity Log'!$A$5:$A$3004,"<="&RptDate,'Activity Log'!$B$5:$B$3004,MgrCrit)) -> 0
B47: =IF(Lists!B8="","",Lists!B8) -> Qatar | C47: =IF($B47="","",COUNTIFS('Leads Pipeline'!$D$5:$D$1004,$B47,'Leads Pipeline'!$F$5:$F$1004,"<>",'Leads Pipeline'!$C$5:$C$1004,MgrCrit)) -> 0 | D47: =IF($B47="","",COUNTIFS('Leads Pipeline'!$D$5:$D$1004,$B47,'Leads Pipeline'!$O$5:$O$1004,"<>Won",'Leads Pipeline'!$O$5:$O$1004,"<>Lost",'Leads Pipeline'!$F$5:$F$1004,"<>",'Leads Pipeline'!$C$5:$C$1004,MgrCrit)) -> 0 | E47: =IF($B47="","",COUNTIFS('Leads Pipeline'!$D$5:$D$1004,$B47,'Leads Pipeline'!$P$5:$P$1004,"Hot",'Leads Pipeline'!$O$5:$O$1004,"<>Won",'Leads Pipeline'!$O$5:$O$1004,"<>Lost",'Leads Pipeline'!$F$5:$F$1004,"<>",'Leads Pipeline'!$C$5:$C$1004,MgrCrit)) -> 0 | F47: =IF($B47="","",COUNTIFS('Leads Pipeline'!$D$5:$D$1004,$B47,'Leads Pipeline'!$O$5:$O$1004,"Offer Sent",'Leads Pipeline'!$C$5:$C$1004,MgrCrit)+COUNTIFS('Leads Pipeline'!$D$5:$D$1004,$B47,'Leads Pipeline'!$O$5:$O$1004,"Negotiation",'Leads Pipeline'!$C$5:$C$1004,MgrCrit)) -> 0 | G47: =IF($B47="","",COUNTIFS('Leads Pipeline'!$D$5:$D$1004,$B47,'Leads Pipeline'!$O$5:$O$1004,"Won",'Leads Pipeline'!$C$5:$C$1004,MgrCrit)) -> 0 | H47: =IF($B47="","",COUNTIFS('Leads Pipeline'!$D$5:$D$1004,$B47,'Leads Pipeline'!$O$5:$O$1004,"Lost",'Leads Pipeline'!$C$5:$C$1004,MgrCrit)) -> 0 | I47: =IF($B47="","",SUMIFS('Leads Pipeline'!$U$5:$U$1004,'Leads Pipeline'!$D$5:$D$1004,$B47,'Leads Pipeline'!$O$5:$O$1004,"<>Won",'Leads Pipeline'!$O$5:$O$1004,"<>Lost",'Leads Pipeline'!$C$5:$C$1004,MgrCrit)) -> 0 | J47: =IF($B47="","",COUNTIFS('Active Clients'!$B$5:$B$504,$B47,'Active Clients'!$T$5:$T$504,"Active",'Active Clients'!$K$5:$K$504,MgrCrit)) -> 0 | K47: =IF($B47="","",SUMIFS('Active Clients'!$R$5:$R$504,'Active Clients'!$B$5:$B$504,$B47,'Active Clients'!$K$5:$K$504,MgrCrit)) -> 0 | L47: =IF($B47="","",COUNTIFS('Activity Log'!$E$5:$E$3004,$B47,'Activity Log'!$A$5:$A$3004,">="&(RptDate-6),'Activity Log'!$A$5:$A$3004,"<="&RptDate,'Activity Log'!$B$5:$B$3004,MgrCrit)) -> 0
B48: =IF(Lists!B9="","",Lists!B9) -> Kuwait | C48: =IF($B48="","",COUNTIFS('Leads Pipeline'!$D$5:$D$1004,$B48,'Leads Pipeline'!$F$5:$F$1004,"<>",'Leads Pipeline'!$C$5:$C$1004,MgrCrit)) -> 0 | D48: =IF($B48="","",COUNTIFS('Leads Pipeline'!$D$5:$D$1004,$B48,'Leads Pipeline'!$O$5:$O$1004,"<>Won",'Leads Pipeline'!$O$5:$O$1004,"<>Lost",'Leads Pipeline'!$F$5:$F$1004,"<>",'Leads Pipeline'!$C$5:$C$1004,MgrCrit)) -> 0 | E48: =IF($B48="","",COUNTIFS('Leads Pipeline'!$D$5:$D$1004,$B48,'Leads Pipeline'!$P$5:$P$1004,"Hot",'Leads Pipeline'!$O$5:$O$1004,"<>Won",'Leads Pipeline'!$O$5:$O$1004,"<>Lost",'Leads Pipeline'!$F$5:$F$1004,"<>",'Leads Pipeline'!$C$5:$C$1004,MgrCrit)) -> 0 | F48: =IF($B48="","",COUNTIFS('Leads Pipeline'!$D$5:$D$1004,$B48,'Leads Pipeline'!$O$5:$O$1004,"Offer Sent",'Leads Pipeline'!$C$5:$C$1004,MgrCrit)+COUNTIFS('Leads Pipeline'!$D$5:$D$1004,$B48,'Leads Pipeline'!$O$5:$O$1004,"Negotiation",'Leads Pipeline'!$C$5:$C$1004,MgrCrit)) -> 0 | G48: =IF($B48="","",COUNTIFS('Leads Pipeline'!$D$5:$D$1004,$B48,'Leads Pipeline'!$O$5:$O$1004,"Won",'Leads Pipeline'!$C$5:$C$1004,MgrCrit)) -> 0 | H48: =IF($B48="","",COUNTIFS('Leads Pipeline'!$D$5:$D$1004,$B48,'Leads Pipeline'!$O$5:$O$1004,"Lost",'Leads Pipeline'!$C$5:$C$1004,MgrCrit)) -> 0 | I48: =IF($B48="","",SUMIFS('Leads Pipeline'!$U$5:$U$1004,'Leads Pipeline'!$D$5:$D$1004,$B48,'Leads Pipeline'!$O$5:$O$1004,"<>Won",'Leads Pipeline'!$O$5:$O$1004,"<>Lost",'Leads Pipeline'!$C$5:$C$1004,MgrCrit)) -> 0 | J48: =IF($B48="","",COUNTIFS('Active Clients'!$B$5:$B$504,$B48,'Active Clients'!$T$5:$T$504,"Active",'Active Clients'!$K$5:$K$504,MgrCrit)) -> 0 | K48: =IF($B48="","",SUMIFS('Active Clients'!$R$5:$R$504,'Active Clients'!$B$5:$B$504,$B48,'Active Clients'!$K$5:$K$504,MgrCrit)) -> 0 | L48: =IF($B48="","",COUNTIFS('Activity Log'!$E$5:$E$3004,$B48,'Activity Log'!$A$5:$A$3004,">="&(RptDate-6),'Activity Log'!$A$5:$A$3004,"<="&RptDate,'Activity Log'!$B$5:$B$3004,MgrCrit)) -> 0
...

Sheet Guide
B1: HOW TO USE THIS CRM
B3: Sheet | C3: What it is for / who fills it
B4: Dashboard | C4: Your daily control screen. Set the report date (default = today) and the manager. Shows activity, follow-ups, overdue tasks, pipeline, country and manager tables.
B5: Leads Pipeline | C5: Every prospect the manager works on. One row per company. Keep Status, Last Contact, Next Action and Next Action Date up to date after every contact.
B6: Active Clients | C6: Existing customers. Update Last Order Date, Last Order Value and Sales YTD after each order; set Next Follow-up.
B7: Activity Log | C7: The manager adds one row for every call, WhatsApp, email, meeting or visit — the same day. Type the Lead ID (L-0001…) or Client ID (C-0001…); company, country and city fill in automatically.
B8: Geography | C8: Breakdown by country and city. Add new cities here so they appear in the City dropdown.
B9: Lists | C9: All dropdown values: managers, countries, statuses, segments, sources, activity types. Rename 'Sales Manager 1' etc. to real names first.
B11: Daily control routine | C11: 1) Open Dashboard → check 'Activities logged' and the 7-day chart (red = no activity on a working day). 2) Check 'Overdue follow-ups' → in Leads Pipeline filter Follow-up Status = Overdue. 3) Filter Activity Log by today's date to read what was discussed. 4) Review Hot leads and Offer / Negotiation by country.
B12: Splitting by country / city | C12: Use the filter arrows in row 4 of any data sheet (Country, City, Manager, Status). The Dashboard 'By Country' table and the Geography sheet give totals.
B13: Colour code | C13: White = enter data · Grey = automatic formula (do not type) · Yellow = settings/lists · Light blue = example row (overwrite it).
B14: Rules | C14: Never delete a lead row — set Status to Lost. Dates as DD.MM.YYYY. Deal values in USD, volumes in litres per month.
B15: Status meaning | C15: New → Contacted → Interested → Samples Sent → Offer Sent → Negotiation → Won / Lost. On Hold = paused by client.

Sheet Lists
A1: LISTS — edit these to change the dropdowns everywhere
A2: Add or rename items directly in the yellow cells. Sales managers and countries flow into the Dashboard tables automatically.
A4: Sales Managers | B4: Countries | C4: Segments | D4: Lead Status | E4: Priority | F4: Lead Source | G4: Activity Types | H4: Outcome | I4: Client Status | J4: Payment Terms | K4: Manager filter
A5: Sales Manager 1 | B5: United Arab Emirates | C5: Distributor | D5: New | E5: Hot | F5: Cold call | G5: Call | H5: Positive | I5: Active | J5: Prepayment | K5: All
A6: Sales Manager 2 | B6: Saudi Arabia | C6: Wholesaler | D6: Contacted | E6: Warm | F6: Exhibition | G6: WhatsApp | H6: Neutral | I6: At Risk | J6: Cash on delivery | K6: =IF(A5="","",A5) -> Sales Manager 1
A7: Sales Manager 3 | B7: Oman | C7: Retailer / Shop | D7: Interested | E7: Cold | F7: Referral | G7: Email | H7: Negative | I7: Inactive | J7: Net 15 | K7: =IF(A6="","",A6) -> Sales Manager 2
B8: Qatar | C8: Workshop / Service | D8: Samples Sent | F8: Website | G8: Meeting | H8: No answer | I8: Suspended | J8: Net 30 | K8: =IF(A7="","",A7) -> Sales Manager 3
B9: Kuwait | C9: Fleet / Transport | D9: Offer Sent | F9: Marketplace | G9: Visit | J9: Net 45 | K9: =IF(A8="","",A8)
B10: Bahrain | C10: Industrial | D10: Negotiation | F10: Social media | G10: Offer sent | J10: Net 60 | K10: =IF(A9="","",A9)
B11: Iraq | C11: Marketplace | D11: Won | F11: Email campaign | G11: Samples sent | J11: Letter of credit | K11: =IF(A10="","",A10)
B12: Jordan | C12: Other | D12: Lost | F12: Walk-in | G12: Order received | K12: =IF(A11="","",A11)
B13: Lebanon | D13: On Hold | F13: Other | G13: Payment follow-up | K13: =IF(A12="","",A12)
B14: Egypt | G14: Other | K14: =IF(A13="","",A13)
B15: Yemen | K15: =IF(A14="","",A14)
B16: Pakistan
B17: India
B18: Afghanistan
B19: Kenya
B20: Tanzania
B21: Uzbekistan
B22: Kazakhstan
B23: Azerbaijan
B24: Georgia

Sheet Geography
A1: GEOGRAPHY — breakdown by country & city
A2: Add new cities in the yellow cells (Country + City); counts update automatically. Cities listed here appear in the City dropdowns.
A4: Country | B4: City | C4: Total Leads | D4: Open Leads | E4: Hot Leads | F4: Won | G4: Open Pipeline (USD) | H4: Active Clients | I4: Sales YTD (USD) | J4: Activities (last 30 days)
A5: United Arab Emirates | B5: Dubai | C5: =IF(AND($A5<>"",$B5<>""),COUNTIFS('Leads Pipeline'!$D$5:$D$1004,$A5,'Leads Pipeline'!$E$5:$E$1004,$B5,'Leads Pipeline'!$F$5:$F$1004,"<>"),"") -> 0 | D5: =IF(AND($A5<>"",$B5<>""),COUNTIFS('Leads Pipeline'!$D$5:$D$1004,$A5,'Leads Pipeline'!$E$5:$E$1004,$B5,'Leads Pipeline'!$F$5:$F$1004,"<>",'Leads Pipeline'!$O$5:$O$1004,"<>Won",'Leads Pipeline'!$O$5:$O$1004,"<>Lost"),"") -> 0 | E5: =IF(AND($A5<>"",$B5<>""),COUNTIFS('Leads Pipeline'!$D$5:$D$1004,$A5,'Leads Pipeline'!$E$5:$E$1004,$B5,'Leads Pipeline'!$P$5:$P$1004,"Hot",'Leads Pipeline'!$O$5:$O$1004,"<>Won",'Leads Pipeline'!$O$5:$O$1004,"<>Lost"),"") -> 0 | F5: =IF(AND($A5<>"",$B5<>""),COUNTIFS('Leads Pipeline'!$D$5:$D$1004,$A5,'Leads Pipeline'!$E$5:$E$1004,$B5,'Leads Pipeline'!$O$5:$O$1004,"Won"),"") -> 0 | G5: =IF(AND($A5<>"",$B5<>""),SUMIFS('Leads Pipeline'!$U$5:$U$1004,'Leads Pipeline'!$D$5:$D$1004,$A5,'Leads Pipeline'!$E$5:$E$1004,$B5,'Leads Pipeline'!$O$5:$O$1004,"<>Won",'Leads Pipeline'!$O$5:$O$1004,"<>Lost"),"") -> 0 | H5: =IF(AND($A5<>"",$B5<>""),COUNTIFS('Active Clients'!$B$5:$B$504,$A5,'Active Clients'!$C$5:$C$504,$B5,'Active Clients'!$T$5:$T$504,"Active"),"") -> 0 | I5: =IF(AND($A5<>"",$B5<>""),SUMIFS('Active Clients'!$R$5:$R$504,'Active Clients'!$B$5:$B$504,$A5,'Active Clients'!$C$5:$C$504,$B5),"") -> 0 | J5: =IF(AND($A5<>"",$B5<>""),COUNTIFS('Activity Log'!$E$5:$E$3004,$A5,'Activity Log'!$F$5:$F$3004,$B5,'Activity Log'!$A$5:$A$3004,">="&(TODAY()-29),'Activity Log'!$A$5:$A$3004,"<="&TODAY()),"") -> 0
A6: United Arab Emirates | B6: Abu Dhabi | C6: =IF(AND($A6<>"",$B6<>""),COUNTIFS('Leads Pipeline'!$D$5:$D$1004,$A6,'Leads Pipeline'!$E$5:$E$1004,$B6,'Leads Pipeline'!$F$5:$F$1004,"<>"),"") -> 0 | D6: =IF(AND($A6<>"",$B6<>""),COUNTIFS('Leads Pipeline'!$D$5:$D$1004,$A6,'Leads Pipeline'!$E$5:$E$1004,$B6,'Leads Pipeline'!$F$5:$F$1004,"<>",'Leads Pipeline'!$O$5:$O$1004,"<>Won",'Leads Pipeline'!$O$5:$O$1004,"<>Lost"),"") -> 0 | E6: =IF(AND($A6<>"",$B6<>""),COUNTIFS('Leads Pipeline'!$D$5:$D$1004,$A6,'Leads Pipeline'!$E$5:$E$1004,$B6,'Leads Pipeline'!$P$5:$P$1004,"Hot",'Leads Pipeline'!$O$5:$O$1004,"<>Won",'Leads Pipeline'!$O$5:$O$1004,"<>Lost"),"") -> 0 | F6: =IF(AND($A6<>"",$B6<>""),COUNTIFS('Leads Pipeline'!$D$5:$D$1004,$A6,'Leads Pipeline'!$E$5:$E$1004,$B6,'Leads Pipeline'!$O$5:$O$1004,"Won"),"") -> 0 | G6: =IF(AND($A6<>"",$B6<>""),SUMIFS('Leads Pipeline'!$U$5:$U$1004,'Leads Pipeline'!$D$5:$D$1004,$A6,'Leads Pipeline'!$E$5:$E$1004,$B6,'Leads Pipeline'!$O$5:$O$1004,"<>Won",'Leads Pipeline'!$O$5:$O$1004,"<>Lost"),"") -> 0 | H6: =IF(AND($A6<>"",$B6<>""),COUNTIFS('Active Clients'!$B$5:$B$504,$A6,'Active Clients'!$C$5:$C$504,$B6,'Active Clients'!$T$5:$T$504,"Active"),"") -> 0 | I6: =IF(AND($A6<>"",$B6<>""),SUMIFS('Active Clients'!$R$5:$R$504,'Active Clients'!$B$5:$B$504,$A6,'Active Clients'!$C$5:$C$504,$B6),"") -> 0 | J6: =IF(AND($A6<>"",$B6<>""),COUNTIFS('Activity Log'!$E$5:$E$3004,$A6,'Activity Log'!$F$5:$F$3004,$B6,'Activity Log'!$A$5:$A$3004,">="&(TODAY()-29),'Activity Log'!$A$5:$A$3004,"<="&TODAY()),"") -> 0
A7: United Arab Emirates | B7: Sharjah | C7: =IF(AND($A7<>"",$B7<>""),COUNTIFS('Leads Pipeline'!$D$5:$D$1004,$A7,'Leads Pipeline'!$E$5:$E$1004,$B7,'Leads Pipeline'!$F$5:$F$1004,"<>"),"") -> 0 | D7: =IF(AND($A7<>"",$B7<>""),COUNTIFS('Leads Pipeline'!$D$5:$D$1004,$A7,'Leads Pipeline'!$E$5:$E$1004,$B7,'Leads Pipeline'!$F$5:$F$1004,"<>",'Leads Pipeline'!$O$5:$O$1004,"<>Won",'Leads Pipeline'!$O$5:$O$1004,"<>Lost"),"") -> 0 | E7: =IF(AND($A7<>"",$B7<>""),COUNTIFS('Leads Pipeline'!$D$5:$D$1004,$A7,'Leads Pipeline'!$E$5:$E$1004,$B7,'Leads Pipeline'!$P$5:$P$1004,"Hot",'Leads Pipeline'!$O$5:$O$1004,"<>Won",'Leads Pipeline'!$O$5:$O$1004,"<>Lost"),"") -> 0 | F7: =IF(AND($A7<>"",$B7<>""),COUNTIFS('Leads Pipeline'!$D$5:$D$1004,$A7,'Leads Pipeline'!$E$5:$E$1004,$B7,'Leads Pipeline'!$O$5:$O$1004,"Won"),"") -> 0 | G7: =IF(AND($A7<>"",$B7<>""),SUMIFS('Leads Pipeline'!$U$5:$U$1004,'Leads Pipeline'!$D$5:$D$1004,$A7,'Leads Pipeline'!$E$5:$E$1004,$B7,'Leads Pipeline'!$O$5:$O$1004,"<>Won",'Leads Pipeline'!$O$5:$O$1004,"<>Lost"),"") -> 0 | H7: =IF(AND($A7<>"",$B7<>""),COUNTIFS('Active Clients'!$B$5:$B$504,$A7,'Active Clients'!$C$5:$C$504,$B7,'Active Clients'!$T$5:$T$504,"Active"),"") -> 1 | I7: =IF(AND($A7<>"",$B7<>""),SUMIFS('Active Clients'!$R$5:$R$504,'Active Clients'!$B$5:$B$504,$A7,'Active Clients'!$C$5:$C$504,$B7),"") -> 64000 | J7: =IF(AND($A7<>"",$B7<>""),COUNTIFS('Activity Log'!$E$5:$E$3004,$A7,'Activity Log'!$F$5:$F$3004,$B7,'Activity Log'!$A$5:$A$3004,">="&(TODAY()-29),'Activity Log'!$A$5:$A$3004,"<="&TODAY()),"") -> 0
A8: United Arab Emirates | B8: Ajman | C8: =IF(AND($A8<>"",$B8<>""),COUNTIFS('Leads Pipeline'!$D$5:$D$1004,$A8,'Leads Pipeline'!$E$5:$E$1004,$B8,'Leads Pipeline'!$F$5:$F$1004,"<>"),"") -> 0 | D8: =IF(AND($A8<>"",$B8<>""),COUNTIFS('Leads Pipeline'!$D$5:$D$1004,$A8,'Leads Pipeline'!$E$5:$E$1004,$B8,'Leads Pipeline'!$F$5:$F$1004,"<>",'Leads Pipeline'!$O$5:$O$1004,"<>Won",'Leads Pipeline'!$O$5:$O$1004,"<>Lost"),"") -> 0 | E8: =IF(AND($A8<>"",$B8<>""),COUNTIFS('Leads Pipeline'!$D$5:$D$1004,$A8,'Leads Pipeline'!$E$5:$E$1004,$B8,'Leads Pipeline'!$P$5:$P$1004,"Hot",'Leads Pipeline'!$O$5:$O$1004,"<>Won",'Leads Pipeline'!$O$5:$O$1004,"<>Lost"),"") -> 0 | F8: =IF(AND($A8<>"",$B8<>""),COUNTIFS('Leads Pipeline'!$D$5:$D$1004,$A8,'Leads Pipeline'!$E$5:$E$1004,$B8,'Leads Pipeline'!$O$5:$O$1004,"Won"),"") -> 0 | G8: =IF(AND($A8<>"",$B8<>""),SUMIFS('Leads Pipeline'!$U$5:$U$1004,'Leads Pipeline'!$D$5:$D$1004,$A8,'Leads Pipeline'!$E$5:$E$1004,$B8,'Leads Pipeline'!$O$5:$O$1004,"<>Won",'Leads Pipeline'!$O$5:$O$1004,"<>Lost"),"") -> 0 | H8: =IF(AND($A8<>"",$B8<>""),COUNTIFS('Active Clients'!$B$5:$B$504,$A8,'Active Clients'!$C$5:$C$504,$B8,'Active Clients'!$T$5:$T$504,"Active"),"") -> 0 | I8: =IF(AND($A8<>"",$B8<>""),SUMIFS('Active Clients'!$R$5:$R$504,'Active Clients'!$B$5:$B$504,$A8,'Active Clients'!$C$5:$C$504,$B8),"") -> 0 | J8: =IF(AND($A8<>"",$B8<>""),COUNTIFS('Activity Log'!$E$5:$E$3004,$A8,'Activity Log'!$F$5:$F$3004,$B8,'Activity Log'!$A$5:$A$3004,">="&(TODAY()-29),'Activity Log'!$A$5:$A$3004,"<="&TODAY()),"") -> 0
A9: United Arab Emirates | B9: Ras Al Khaimah | C9: =IF(AND($A9<>"",$B9<>""),COUNTIFS('Leads Pipeline'!$D$5:$D$1004,$A9,'Leads Pipeline'!$E$5:$E$1004,$B9,'Leads Pipeline'!$F$5:$F$1004,"<>"),"") -> 0 | D9: =IF(AND($A9<>"",$B9<>""),COUNTIFS('Leads Pipeline'!$D$5:$D$1004,$A9,'Leads Pipeline'!$E$5:$E$1004,$B9,'Leads Pipeline'!$F$5:$F$1004,"<>",'Leads Pipeline'!$O$5:$O$1004,"<>Won",'Leads Pipeline'!$O$5:$O$1004,"<>Lost"),"") -> 0 | E9: =IF(AND($A9<>"",$B9<>""),COUNTIFS('Leads Pipeline'!$D$5:$D$1004,$A9,'Leads Pipeline'!$E$5:$E$1004,$B9,'Leads Pipeline'!$P$5:$P$1004,"Hot",'Leads Pipeline'!$O$5:$O$1004,"<>Won",'Leads Pipeline'!$O$5:$O$1004,"<>Lost"),"") -> 0 | F9: =IF(AND($A9<>"",$B9<>""),COUNTIFS('Leads Pipeline'!$D$5:$D$1004,$A9,'Leads Pipeline'!$E$5:$E$1004,$B9,'Leads Pipeline'!$O$5:$O$1004,"Won"),"") -> 0 | G9: =IF(AND($A9<>"",$B9<>""),SUMIFS('Leads Pipeline'!$U$5:$U$1004,'Leads Pipeline'!$D$5:$D$1004,$A9,'Leads Pipeline'!$E$5:$E$1004,$B9,'Leads Pipeline'!$O$5:$O$1004,"<>Won",'Leads Pipeline'!$O$5:$O$1004,"<>Lost"),"") -> 0 | H9: =IF(AND($A9<>"",$B9<>""),COUNTIFS('Active Clients'!$B$5:$B$504,$A9,'Active Clients'!$C$5:$C$504,$B9,'Active Clients'!$T$5:$T$504,"Active"),"") -> 0 | I9: =IF(AND($A9<>"",$B9<>""),SUMIFS('Active Clients'!$R$5:$R$504,'Active Clients'!$B$5:$B$504,$A9,'Active Clients'!$C$5:$C$504,$B9),"") -> 0 | J9: =IF(AND($A9<>"",$B9<>""),COUNTIFS('Activity Log'!$E$5:$E$3004,$A9,'Activity Log'!$F$5:$F$3004,$B9,'Activity Log'!$A$5:$A$3004,">="&(TODAY()-29),'Activity Log'!$A$5:$A$3004,"<="&TODAY()),"") -> 0
A10: United Arab Emirates | B10: Fujairah | C10: =IF(AND($A10<>"",$B10<>""),COUNTIFS('Leads Pipeline'!$D$5:$D$1004,$A10,'Leads Pipeline'!$E$5:$E$1004,$B10,'Leads Pipeline'!$F$5:$F$1004,"<>"),"") -> 0 | D10: =IF(AND($A10<>"",$B10<>""),COUNTIFS('Leads Pipeline'!$D$5:$D$1004,$A10,'Leads Pipeline'!$E$5:$E$1004,$B10,'Leads Pipeline'!$F$5:$F$1004,"<>",'Leads Pipeline'!$O$5:$O$1004,"<>Won",'Leads Pipeline'!$O$5:$O$1004,"<>Lost"),"") -> 0 | E10: =IF(AND($A10<>"",$B10<>""),COUNTIFS('Leads Pipeline'!$D$5:$D$1004,$A10,'Leads Pipeline'!$E$5:$E$1004,$B10,'Leads Pipeline'!$P$5:$P$1004,"Hot",'Leads Pipeline'!$O$5:$O$1004,"<>Won",'Leads Pipeline'!$O$5:$O$1004,"<>Lost"),"") -> 0 | F10: =IF(AND($A10<>"",$B10<>""),COUNTIFS('Leads Pipeline'!$D$5:$D$1004,$A10,'Leads Pipeline'!$E$5:$E$1004,$B10,'Leads Pipeline'!$O$5:$O$1004,"Won"),"") -> 0 | G10: =IF(AND($A10<>"",$B10<>""),SUMIFS('Leads Pipeline'!$U$5:$U$1004,'Leads Pipeline'!$D$5:$D$1004,$A10,'Leads Pipeline'!$E$5:$E$1004,$B10,'Leads Pipeline'!$O$5:$O$1004,"<>Won",'Leads Pipeline'!$O$5:$O$1004,"<>Lost"),"") -> 0 | H10: =IF(AND($A10<>"",$B10<>""),COUNTIFS('Active Clients'!$B$5:$B$504,$A10,'Active Clients'!$C$5:$C$504,$B10,'Active Clients'!$T$5:$T$504,"Active"),"") -> 0 | I10: =IF(AND($A10<>"",$B10<>""),SUMIFS('Active Clients'!$R$5:$R$504,'Active Clients'!$B$5:$B$504,$A10,'Active Clients'!$C$5:$C$504,$B10),"") -> 0 | J10: =IF(AND($A10<>"",$B10<>""),COUNTIFS('Activity Log'!$E$5:$E$3004,$A10,'Activity Log'!$F$5:$F$3004,$B10,'Activity Log'!$A$5:$A$3004,">="&(TODAY()-29),'Activity Log'!$A$5:$A$3004,"<="&TODAY()),"") -> 0
A11: United Arab Emirates | B11: Al Ain | C11: =IF(AND($A11<>"",$B11<>""),COUNTIFS('Leads Pipeline'!$D$5:$D$1004,$A11,'Leads Pipeline'!$E$5:$E$1004,$B11,'Leads Pipeline'!$F$5:$F$1004,"<>"),"") -> 0 | D11: =IF(AND($A11<>"",$B11<>""),COUNTIFS('Leads Pipeline'!$D$5:$D$1004,$A11,'Leads Pipeline'!$E$5:$E$1004,$B11,'Leads Pipeline'!$F$5:$F$1004,"<>",'Leads Pipeline'!$O$5:$O$1004,"<>Won",'Leads Pipeline'!$O$5:$O$1004,"<>Lost"),"") -> 0 | E11: =IF(AND($A11<>"",$B11<>""),COUNTIFS('Leads Pipeline'!$D$5:$D$1004,$A11,'Leads Pipeline'!$E$5:$E$1004,$B11,'Leads Pipeline'!$P$5:$P$1004,"Hot",'Leads Pipeline'!$O$5:$O$1004,"<>Won",'Leads Pipeline'!$O$5:$O$1004,"<>Lost"),"") -> 0 | F11: =IF(AND($A11<>"",$B11<>""),COUNTIFS('Leads Pipeline'!$D$5:$D$1004,$A11,'Leads Pipeline'!$E$5:$E$1004,$B11,'Leads Pipeline'!$O$5:$O$1004,"Won"),"") -> 0 | G11: =IF(AND($A11<>"",$B11<>""),SUMIFS('Leads Pipeline'!$U$5:$U$1004,'Leads Pipeline'!$D$5:$D$1004,$A11,'Leads Pipeline'!$E$5:$E$1004,$B11,'Leads Pipeline'!$O$5:$O$1004,"<>Won",'Leads Pipeline'!$O$5:$O$1004,"<>Lost"),"") -> 0 | H11: =IF(AND($A11<>"",$B11<>""),COUNTIFS('Active Clients'!$B$5:$B$504,$A11,'Active Clients'!$C$5:$C$504,$B11,'Active Clients'!$T$5:$T$504,"Active"),"") -> 0 | I11: =IF(AND($A11<>"",$B11<>""),SUMIFS('Active Clients'!$R$5:$R$504,'Active Clients'!$B$5:$B$504,$A11,'Active Clients'!$C$5:$C$504,$B11),"") -> 0 | J11: =IF(AND($A11<>"",$B11<>""),COUNTIFS('Activity Log'!$E$5:$E$3004,$A11,'Activity Log'!$F$5:$F$3004,$B11,'Activity Log'!$A$5:$A$3004,">="&(TODAY()-29),'Activity Log'!$A$5:$A$3004,"<="&TODAY()),"") -> 0
A12: Saudi Arabia | B12: Riyadh | C12: =IF(AND($A12<>"",$B12<>""),COUNTIFS('Leads Pipeline'!$D$5:$D$1004,$A12,'Leads Pipeline'!$E$5:$E$1004,$B12,'Leads Pipeline'!$F$5:$F$1004,"<>"),"") -> 1 | D12: =IF(AND($A12<>"",$B12<>""),COUNTIFS('Leads Pipeline'!$D$5:$D$1004,$A12,'Leads Pipeline'!$E$5:$E$1004,$B12,'Leads Pipeline'!$F$5:$F$1004,"<>",'Leads Pipeline'!$O$5:$O$1004,"<>Won",'Leads Pipeline'!$O$5:$O$1004,"<>Lost"),"") -> 1 | E12: =IF(AND($A12<>"",$B12<>""),COUNTIFS('Leads Pipeline'!$D$5:$D$1004,$A12,'Leads Pipeline'!$E$5:$E$1004,$B12,'Leads Pipeline'!$P$5:$P$1004,"Hot",'Leads Pipeline'!$O$5:$O$1004,"<>Won",'Leads Pipeline'!$O$5:$O$1004,"<>Lost"),"") -> 1 | F12: =IF(AND($A12<>"",$B12<>""),COUNTIFS('Leads Pipeline'!$D$5:$D$1004,$A12,'Leads Pipeline'!$E$5:$E$1004,$B12,'Leads Pipeline'!$O$5:$O$1004,"Won"),"") -> 0 | G12: =IF(AND($A12<>"",$B12<>""),SUMIFS('Leads Pipeline'!$U$5:$U$1004,'Leads Pipeline'!$D$5:$D$1004,$A12,'Leads Pipeline'!$E$5:$E$1004,$B12,'Leads Pipeline'!$O$5:$O$1004,"<>Won",'Leads Pipeline'!$O$5:$O$1004,"<>Lost"),"") -> 25000 | H12: =IF(AND($A12<>"",$B12<>""),COUNTIFS('Active Clients'!$B$5:$B$504,$A12,'Active Clients'!$C$5:$C$504,$B12,'Active Clients'!$T$5:$T$504,"Active"),"") -> 0 | I12: =IF(AND($A12<>"",$B12<>""),SUMIFS('Active Clients'!$R$5:$R$504,'Active Clients'!$B$5:$B$504,$A12,'Active Clients'!$C$5:$C$504,$B12),"") -> 0 | J12: =IF(AND($A12<>"",$B12<>""),COUNTIFS('Activity Log'!$E$5:$E$3004,$A12,'Activity Log'!$F$5:$F$3004,$B12,'Activity Log'!$A$5:$A$3004,">="&(TODAY()-29),'Activity Log'!$A$5:$A$3004,"<="&TODAY()),"") -> 1
A13: Saudi Arabia | B13: Jeddah | C13: =IF(AND($A13<>"",$B13<>""),COUNTIFS('Leads Pipeline'!$D$5:$D$1004,$A13,'Leads Pipeline'!$E$5:$E$1004,$B13,'Leads Pipeline'!$F$5:$F$1004,"<>"),"") -> 0 | D13: =IF(AND($A13<>"",$B13<>""),COUNTIFS('Leads Pipeline'!$D$5:$D$1004,$A13,'Leads Pipeline'!$E$5:$E$1004,$B13,'Leads Pipeline'!$F$5:$F$1004,"<>",'Leads Pipeline'!$O$5:$O$1004,"<>Won",'Leads Pipeline'!$O$5:$O$1004,"<>Lost"),"") -> 0 | E13: =IF(AND($A13<>"",$B13<>""),COUNTIFS('Leads Pipeline'!$D$5:$D$1004,$A13,'Leads Pipeline'!$E$5:$E$1004,$B13,'Leads Pipeline'!$P$5:$P$1004,"Hot",'Leads Pipeline'!$O$5:$O$1004,"<>Won",'Leads Pipeline'!$O$5:$O$1004,"<>Lost"),"") -> 0 | F13: =IF(AND($A13<>"",$B13<>""),COUNTIFS('Leads Pipeline'!$D$5:$D$1004,$A13,'Leads Pipeline'!$E$5:$E$1004,$B13,'Leads Pipeline'!$O$5:$O$1004,"Won"),"") -> 0 | G13: =IF(AND($A13<>"",$B13<>""),SUMIFS('Leads Pipeline'!$U$5:$U$1004,'Leads Pipeline'!$D$5:$D$1004,$A13,'Leads Pipeline'!$E$5:$E$1004,$B13,'Leads Pipeline'!$O$5:$O$1004,"<>Won",'Leads Pipeline'!$O$5:$O$1004,"<>Lost"),"") -> 0 | H13: =IF(AND($A13<>"",$B13<>""),COUNTIFS('Active Clients'!$B$5:$B$504,$A13,'Active Clients'!$C$5:$C$504,$B13,'Active Clients'!$T$5:$T$504,"Active"),"") -> 0 | I13: =IF(AND($A13<>"",$B13<>""),SUMIFS('Active Clients'!$R$5:$R$504,'Active Clients'!$B$5:$B$504,$A13,'Active Clients'!$C$5:$C$504,$B13),"") -> 0 | J13: =IF(AND($A13<>"",$B13<>""),COUNTIFS('Activity Log'!$E$5:$E$3004,$A13,'Activity Log'!$F$5:$F$3004,$B13,'Activity Log'!$A$5:$A$3004,">="&(TODAY()-29),'Activity Log'!$A$5:$A$3004,"<="&TODAY()),"") -> 0
A14: Saudi Arabia | B14: Dammam | C14: =IF(AND($A14<>"",$B14<>""),COUNTIFS('Leads Pipeline'!$D$5:$D$1004,$A14,'Leads Pipeline'!$E$5:$E$1004,$B14,'Leads Pipeline'!$F$5:$F$1004,"<>"),"") -> 0 | D14: =IF(AND($A14<>"",$B14<>""),COUNTIFS('Leads Pipeline'!$D$5:$D$1004,$A14,'Leads Pipeline'!$E$5:$E$1004,$B14,'Leads Pipeline'!$F$5:$F$1004,"<>",'Leads Pipeline'!$O$5:$O$1004,"<>Won",'Leads Pipeline'!$O$5:$O$1004,"<>Lost"),"") -> 0 | E14: =IF(AND($A14<>"",$B14<>""),COUNTIFS('Leads Pipeline'!$D$5:$D$1004,$A14,'Leads Pipeline'!$E$5:$E$1004,$B14,'Leads Pipeline'!$P$5:$P$1004,"Hot",'Leads Pipeline'!$O$5:$O$1004,"<>Won",'Leads Pipeline'!$O$5:$O$1004,"<>Lost"),"") -> 0 | F14: =IF(AND($A14<>"",$B14<>""),COUNTIFS('Leads Pipeline'!$D$5:$D$1004,$A14,'Leads Pipeline'!$E$5:$E$1004,$B14,'Leads Pipeline'!$O$5:$O$1004,"Won"),"") -> 0 | G14: =IF(AND($A14<>"",$B14<>""),SUMIFS('Leads Pipeline'!$U$5:$U$1004,'Leads Pipeline'!$D$5:$D$1004,$A14,'Leads Pipeline'!$E$5:$E$1004,$B14,'Leads Pipeline'!$O$5:$O$1004,"<>Won",'Leads Pipeline'!$O$5:$O$1004,"<>Lost"),"") -> 0 | H14: =IF(AND($A14<>"",$B14<>""),COUNTIFS('Active Clients'!$B$5:$B$504,$A14,'Active Clients'!$C$5:$C$504,$B14,'Active Clients'!$T$5:$T$504,"Active"),"") -> 0 | I14: =IF(AND($A14<>"",$B14<>""),SUMIFS('Active Clients'!$R$5:$R$504,'Active Clients'!$B$5:$B$504,$A14,'Active Clients'!$C$5:$C$504,$B14),"") -> 0 | J14: =IF(AND($A14<>"",$B14<>""),COUNTIFS('Activity Log'!$E$5:$E$3004,$A14,'Activity Log'!$F$5:$F$3004,$B14,'Activity Log'!$A$5:$A$3004,">="&(TODAY()-29),'Activity Log'!$A$5:$A$3004,"<="&TODAY()),"") -> 0
A15: Saudi Arabia | B15: Mecca | C15: =IF(AND($A15<>"",$B15<>""),COUNTIFS('Leads Pipeline'!$D$5:$D$1004,$A15,'Leads Pipeline'!$E$5:$E$1004,$B15,'Leads Pipeline'!$F$5:$F$1004,"<>"),"") -> 0 | D15: =IF(AND($A15<>"",$B15<>""),COUNTIFS('Leads Pipeline'!$D$5:$D$1004,$A15,'Leads Pipeline'!$E$5:$E$1004,$B15,'Leads Pipeline'!$F$5:$F$1004,"<>",'Leads Pipeline'!$O$5:$O$1004,"<>Won",'Leads Pipeline'!$O$5:$O$1004,"<>Lost"),"") -> 0 | E15: =IF(AND($A15<>"",$B15<>""),COUNTIFS('Leads Pipeline'!$D$5:$D$1004,$A15,'Leads Pipeline'!$E$5:$E$1004,$B15,'Leads Pipeline'!$P$5:$P$1004,"Hot",'Leads Pipeline'!$O$5:$O$1004,"<>Won",'Leads Pipeline'!$O$5:$O$1004,"<>Lost"),"") -> 0 | F15: =IF(AND($A15<>"",$B15<>""),COUNTIFS('Leads Pipeline'!$D$5:$D$1004,$A15,'Leads Pipeline'!$E$5:$E$1004,$B15,'Leads Pipeline'!$O$5:$O$1004,"Won"),"") -> 0 | G15: =IF(AND($A15<>"",$B15<>""),SUMIFS('Leads Pipeline'!$U$5:$U$1004,'Leads Pipeline'!$D$5:$D$1004,$A15,'Leads Pipeline'!$E$5:$E$1004,$B15,'Leads Pipeline'!$O$5:$O$1004,"<>Won",'Leads Pipeline'!$O$5:$O$1004,"<>Lost"),"") -> 0 | H15: =IF(AND($A15<>"",$B15<>""),COUNTIFS('Active Clients'!$B$5:$B$504,$A15,'Active Clients'!$C$5:$C$504,$B15,'Active Clients'!$T$5:$T$504,"Active"),"") -> 0 | I15: =IF(AND($A15<>"",$B15<>""),SUMIFS('Active Clients'!$R$5:$R$504,'Active Clients'!$B$5:$B$504,$A15,'Active Clients'!$C$5:$C$504,$B15),"") -> 0 | J15: =IF(AND($A15<>"",$B15<>""),COUNTIFS('Activity Log'!$E$5:$E$3004,$A15,'Activity Log'!$F$5:$F$3004,$B15,'Activity Log'!$A$5:$A$3004,">="&(TODAY()-29),'Activity Log'!$A$5:$A$3004,"<="&TODAY()),"") -> 0
A16: Saudi Arabia | B16: Medina | C16: =IF(AND($A16<>"",$B16<>""),COUNTIFS('Leads Pipeline'!$D$5:$D$1004,$A16,'Leads Pipeline'!$E$5:$E$1004,$B16,'Leads Pipeline'!$F$5:$F$1004,"<>"),"") -> 0 | D16: =IF(AND($A16<>"",$B16<>""),COUNTIFS('Leads Pipeline'!$D$5:$D$1004,$A16,'Leads Pipeline'!$E$5:$E$1004,$B16,'Leads Pipeline'!$F$5:$F$1004,"<>",'Leads Pipeline'!$O$5:$O$1004,"<>Won",'Leads Pipeline'!$O$5:$O$1004,"<>Lost"),"") -> 0 | E16: =IF(AND($A16<>"",$B16<>""),COUNTIFS('Leads Pipeline'!$D$5:$D$1004,$A16,'Leads Pipeline'!$E$5:$E$1004,$B16,'Leads Pipeline'!$P$5:$P$1004,"Hot",'Leads Pipeline'!$O$5:$O$1004,"<>Won",'Leads Pipeline'!$O$5:$O$1004,"<>Lost"),"") -> 0 | F16: =IF(AND($A16<>"",$B16<>""),COUNTIFS('Leads Pipeline'!$D$5:$D$1004,$A16,'Leads Pipeline'!$E$5:$E$1004,$B16,'Leads Pipeline'!$O$5:$O$1004,"Won"),"") -> 0 | G16: =IF(AND($A16<>"",$B16<>""),SUMIFS('Leads Pipeline'!$U$5:$U$1004,'Leads Pipeline'!$D$5:$D$1004,$A16,'Leads Pipeline'!$E$5:$E$1004,$B16,'Leads Pipeline'!$O$5:$O$1004,"<>Won",'Leads Pipeline'!$O$5:$O$1004,"<>Lost"),"") -> 0 | H16: =IF(AND($A16<>"",$B16<>""),COUNTIFS('Active Clients'!$B$5:$B$504,$A16,'Active Clients'!$C$5:$C$504,$B16,'Active Clients'!$T$5:$T$504,"Active"),"") -> 0 | I16: =IF(AND($A16<>"",$B16<>""),SUMIFS('Active Clients'!$R$5:$R$504,'Active Clients'!$B$5:$B$504,$A16,'Active Clients'!$C$5:$C$504,$B16),"") -> 0 | J16: =IF(AND($A16<>"",$B16<>""),COUNTIFS('Activity Log'!$E$5:$E$3004,$A16,'Activity Log'!$F$5:$F$3004,$B16,'Activity Log'!$A$5:$A$3004,">="&(TODAY()-29),'Activity Log'!$A$5:$A$3004,"<="&TODAY()),"") -> 0
... A43: Georgia | B43: Tbilisi | C43: =IF(AND($A43<>"",$B43<>""),COUNTIFS('Leads Pipeline'!$D$5:$D$1004,$A43,'Leads Pipeline'!$E$5:$E$1004,$B43,'Leads Pipeline'!$F$5:$F$1004,"<>"),"") -> 0 | D43: =IF(AND($A43<>"",$B43<>""),COUNTIFS('Leads Pipeline'!$D$5:$D$1004,$A43,'Leads Pipeline'!$E$5:$E$1004,$B43,'Leads Pipeline'!$F$5:$F$1004,"<>",'Leads Pipeline'!$O$5:$O$1004,"<>Won",'Leads Pipeline'!$O$5:$O$1004,"<>Lost"),"") -> 0 | E43: =IF(AND($A43<>"",$B43<>""),COUNTIFS('Leads Pipeline'!$D$5:$D$1004,$A43,'Leads Pipeline'!$E$5:$E$1004,$B43,'Leads Pipeline'!$P$5:$P$1004,"Hot",'Leads Pipeline'!$O$5:$O$1004,"<>Won",'Leads Pipeline'!$O$5:$O$1004,"<>Lost"),"") -> 0 | F43: =IF(AND($A43<>"",$B43<>""),COUNTIFS('Leads Pipeline'!$D$5:$D$1004,$A43,'Leads Pipeline'!$E$5:$E$1004,$B43,'Leads Pipeline'!$O$5:$O$1004,"Won"),"") -> 0 | G43: =IF(AND($A43<>"",$B43<>""),SUMIFS('Leads Pipeline'!$U$5:$U$1004,'Leads Pipeline'!$D$5:$D$1004,$A43,'Leads Pipeline'!$E$5:$E$1004,$B43,'Leads Pipeline'!$O$5:$O$1004,"<>Won",'Leads Pipeline'!$O$5:$O$1004,"<>Lost"),"") -> 0 | H43: =IF(AND($A43<>"",$B43<>""),COUNTIFS('Active Clients'!$B$5:$B$504,$A43,'Active Clients'!$C$5:$C$504,$B43,'Active Clients'!$T$5:$T$504,"Active"),"") -> 0 | I43: =IF(AND($A43<>"",$B43<>""),SUMIFS('Active Clients'!$R$5:$R$504,'Active Clients'!$B$5:$B$504,$A43,'Active Clients'!$C$5:$C$504,$B43),"") -> 0 | J43: =IF(AND($A43<>"",$B43<>""),COUNTIFS('Activity Log'!$E$5:$E$3004,$A43,'Activity Log'!$F$5:$F$3004,$B43,'Activity Log'!$A$5:$A$3004,">="&(TODAY()-29),'Activity Log'!$A$5:$A$3004,"<="&TODAY()),"") -> 0
C44: =IF(AND($A44<>"",$B44<>""),COUNTIFS('Leads Pipeline'!$D$5:$D$1004,$A44,'Leads Pipeline'!$E$5:$E$1004,$B44,'Leads Pipeline'!$F$5:$F$1004,"<>"),"") | D44: =IF(AND($A44<>"",$B44<>""),COUNTIFS('Leads Pipeline'!$D$5:$D$1004,$A44,'Leads Pipeline'!$E$5:$E$1004,$B44,'Leads Pipeline'!$F$5:$F$1004,"<>",'Leads Pipeline'!$O$5:$O$1004,"<>Won",'Leads Pipeline'!$O$5:$O$1004,"<>Lost"),"") | E44: =IF(AND($A44<>"",$B44<>""),COUNTIFS('Leads Pipeline'!$D$5:$D$1004,$A44,'Leads Pipeline'!$E$5:$E$1004,$B44,'Leads Pipeline'!$P$5:$P$1004,"Hot",'Leads Pipeline'!$O$5:$O$1004,"<>Won",'Leads Pipeline'!$O$5:$O$1004,"<>Lost"),"") | F44: =IF(AND($A44<>"",$B44<>""),COUNTIFS('Leads Pipeline'!$D$5:$D$1004,$A44,'Leads Pipeline'!$E$5:$E$1004,$B44,'Leads Pipeline'!$O$5:$O$1004,"Won"),"") | G44: =IF(AND($A44<>"",$B44<>""),SUMIFS('Leads Pipeline'!$U$5:$U$1004,'Leads Pipeline'!$D$5:$D$1004,$A44,'Leads Pipeline'!$E$5:$E$1004,$B44,'Leads Pipeline'!$O$5:$O$1004,"<>Won",'Leads Pipeline'!$O$5:$O$1004,"<>Lost"),"") | H44: =IF(AND($A44<>"",$B44<>""),COUNTIFS('Active Clients'!$B$5:$B$504,$A44,'Active Clients'!$C$5:$C$504,$B44,'Active Clients'!$T$5:$T$504,"Active"),"") | I44: =IF(AND($A44<>"",$B44<>""),SUMIFS('Active Clients'!$R$5:$R$504,'Active Clients'!$B$5:$B$504,$A44,'Active Clients'!$C$5:$C$504,$B44),"") | J44: =IF(AND($A44<>"",$B44<>""),COUNTIFS('Activity Log'!$E$5:$E$3004,$A44,'Activity Log'!$F$5:$F$3004,$B44,'Activity Log'!$A$5:$A$3004,">="&(TODAY()-29),'Activity Log'!$A$5:$A$3004,"<="&TODAY()),"")
C45: =IF(AND($A45<>"",$B45<>""),COUNTIFS('Leads Pipeline'!$D$5:$D$1004,$A45,'Leads Pipeline'!$E$5:$E$1004,$B45,'Leads Pipeline'!$F$5:$F$1004,"<>"),"") | D45: =IF(AND($A45<>"",$B45<>""),COUNTIFS('Leads Pipeline'!$D$5:$D$1004,$A45,'Leads Pipeline'!$E$5:$E$1004,$B45,'Leads Pipeline'!$F$5:$F$1004,"<>",'Leads Pipeline'!$O$5:$O$1004,"<>Won",'Leads Pipeline'!$O$5:$O$1004,"<>Lost"),"") | E45: =IF(AND($A45<>"",$B45<>""),COUNTIFS('Leads Pipeline'!$D$5:$D$1004,$A45,'Leads Pipeline'!$E$5:$E$1004,$B45,'Leads Pipeline'!$P$5:$P$1004,"Hot",'Leads Pipeline'!$O$5:$O$1004,"<>Won",'Leads Pipeline'!$O$5:$O$1004,"<>Lost"),"") | F45: =IF(AND($A45<>"",$B45<>""),COUNTIFS('Leads Pipeline'!$D$5:$D$1004,$A45,'Leads Pipeline'!$E$5:$E$1004,$B45,'Leads Pipeline'!$O$5:$O$1004,"Won"),"") | G45: =IF(AND($A45<>"",$B45<>""),SUMIFS('Leads Pipeline'!$U$5:$U$1004,'Leads Pipeline'!$D$5:$D$1004,$A45,'Leads Pipeline'!$E$5:$E$1004,$B45,'Leads Pipeline'!$O$5:$O$1004,"<>Won",'Leads Pipeline'!$O$5:$O$1004,"<>Lost"),"") | H45: =IF(AND($A45<>"",$B45<>""),COUNTIFS('Active Clients'!$B$5:$B$504,$A45,'Active Clients'!$C$5:$C$504,$B45,'Active Clients'!$T$5:$T$504,"Active"),"") | I45: =IF(AND($A45<>"",$B45<>""),SUMIFS('Active Clients'!$R$5:$R$504,'Active Clients'!$B$5:$B$504,$A45,'Active Clients'!$C$5:$C$504,$B45),"") | J45: =IF(AND($A45<>"",$B45<>""),COUNTIFS('Activity Log'!$E$5:$E$3004,$A45,'Activity Log'!$F$5:$F$3004,$B45,'Activity Log'!$A$5:$A$3004,">="&(TODAY()-29),'Activity Log'!$A$5:$A$3004,"<="&TODAY()),"")
C46: =IF(AND($A46<>"",$B46<>""),COUNTIFS('Leads Pipeline'!$D$5:$D$1004,$A46,'Leads Pipeline'!$E$5:$E$1004,$B46,'Leads Pipeline'!$F$5:$F$1004,"<>"),"") | D46: =IF(AND($A46<>"",$B46<>""),COUNTIFS('Leads Pipeline'!$D$5:$D$1004,$A46,'Leads Pipeline'!$E$5:$E$1004,$B46,'Leads Pipeline'!$F$5:$F$1004,"<>",'Leads Pipeline'!$O$5:$O$1004,"<>Won",'Leads Pipeline'!$O$5:$O$1004,"<>Lost"),"") | E46: =IF(AND($A46<>"",$B46<>""),COUNTIFS('Leads Pipeline'!$D$5:$D$1004,$A46,'Leads Pipeline'!$E$5:$E$1004,$B46,'Leads Pipeline'!$P$5:$P$1004,"Hot",'Leads Pipeline'!$O$5:$O$1004,"<>Won",'Leads Pipeline'!$O$5:$O$1004,"<>Lost"),"") | F46: =IF(AND($A46<>"",$B46<>""),COUNTIFS('Leads Pipeline'!$D$5:$D$1004,$A46,'Leads Pipeline'!$E$5:$E$1004,$B46,'Leads Pipeline'!$O$5:$O$1004,"Won"),"") | G46: =IF(AND($A46<>"",$B46<>""),SUMIFS('Leads Pipeline'!$U$5:$U$1004,'Leads Pipeline'!$D$5:$D$1004,$A46,'Leads Pipeline'!$E$5:$E$1004,$B46,'Leads Pipeline'!$O$5:$O$1004,"<>Won",'Leads Pipeline'!$O$5:$O$1004,"<>Lost"),"") | H46: =IF(AND($A46<>"",$B46<>""),COUNTIFS('Active Clients'!$B$5:$B$504,$A46,'Active Clients'!$C$5:$C$504,$B46,'Active Clients'!$T$5:$T$504,"Active"),"") | I46: =IF(AND($A46<>"",$B46<>""),SUMIFS('Active Clients'!$R$5:$R$504,'Active Clients'!$B$5:$B$504,$A46,'Active Clients'!$C$5:$C$504,$B46),"") | J46: =IF(AND($A46<>"",$B46<>""),COUNTIFS('Activity Log'!$E$5:$E$3004,$A46,'Activity Log'!$F$5:$F$3004,$B46,'Activity Log'!$A$5:$A$3004,">="&(TODAY()-29),'Activity Log'!$A$5:$A$3004,"<="&TODAY()),"")
C47: =IF(AND($A47<>"",$B47<>""),COUNTIFS('Leads Pipeline'!$D$5:$D$1004,$A47,'Leads Pipeline'!$E$5:$E$1004,$B47,'Leads Pipeline'!$F$5:$F$1004,"<>"),"") | D47: =IF(AND($A47<>"",$B47<>""),COUNTIFS('Leads Pipeline'!$D$5:$D$1004,$A47,'Leads Pipeline'!$E$5:$E$1004,$B47,'Leads Pipeline'!$F$5:$F$1004,"<>",'Leads Pipeline'!$O$5:$O$1004,"<>Won",'Leads Pipeline'!$O$5:$O$1004,"<>Lost"),"") | E47: =IF(AND($A47<>"",$B47<>""),COUNTIFS('Leads Pipeline'!$D$5:$D$1004,$A47,'Leads Pipeline'!$E$5:$E$1004,$B47,'Leads Pipeline'!$P$5:$P$1004,"Hot",'Leads Pipeline'!$O$5:$O$1004,"<>Won",'Leads Pipeline'!$O$5:$O$1004,"<>Lost"),"") | F47: =IF(AND($A47<>"",$B47<>""),COUNTIFS('Leads Pipeline'!$D$5:$D$1004,$A47,'Leads Pipeline'!$E$5:$E$1004,$B47,'Leads Pipeline'!$O$5:$O$1004,"Won"),"") | G47: =IF(AND($A47<>"",$B47<>""),SUMIFS('Leads Pipeline'!$U$5:$U$1004,'Leads Pipeline'!$D$5:$D$1004,$A47,'Leads Pipeline'!$E$5:$E$1004,$B47,'Leads Pipeline'!$O$5:$O$1004,"<>Won",'Leads Pipeline'!$O$5:$O$1004,"<>Lost"),"") | H47: =IF(AND($A47<>"",$B47<>""),COUNTIFS('Active Clients'!$B$5:$B$504,$A47,'Active Clients'!$C$5:$C$504,$B47,'Active Clients'!$T$5:$T$504,"Active"),"") | I47: =IF(AND($A47<>"",$B47<>""),SUMIFS('Active Clients'!$R$5:$R$504,'Active Clients'!$B$5:$B$504,$A47,'Active Clients'!$C$5:$C$504,$B47),"") | J47: =IF(AND($A47<>"",$B47<>""),COUNTIFS('Activity Log'!$E$5:$E$3004,$A47,'Activity Log'!$F$5:$F$3004,$B47,'Activity Log'!$A$5:$A$3004,">="&(TODAY()-29),'Activity Log'!$A$5:$A$3004,"<="&TODAY()),"")
C48: =IF(AND($A48<>"",$B48<>""),COUNTIFS('Leads Pipeline'!$D$5:$D$1004,$A48,'Leads Pipeline'!$E$5:$E$1004,$B48,'Leads Pipeline'!$F$5:$F$1004,"<>"),"") | D48: =IF(AND($A48<>"",$B48<>""),COUNTIFS('Leads Pipeline'!$D$5:$D$1004,$A48,'Leads Pipeline'!$E$5:$E$1004,$B48,'Leads Pipeline'!$F$5:$F$1004,"<>",'Leads Pipeline'!$O$5:$O$1004,"<>Won",'Leads Pipeline'!$O$5:$O$1004,"<>Lost"),"") | E48: =IF(AND($A48<>"",$B48<>""),COUNTIFS('Leads Pipeline'!$D$5:$D$1004,$A48,'Leads Pipeline'!$E$5:$E$1004,$B48,'Leads Pipeline'!$P$5:$P$1004,"Hot",'Leads Pipeline'!$O$5:$O$1004,"<>Won",'Leads Pipeline'!$O$5:$O$1004,"<>Lost"),"") | F48: =IF(AND($A48<>"",$B48<>""),COUNTIFS('Leads Pipeline'!$D$5:$D$1004,$A48,'Leads Pipeline'!$E$5:$E$1004,$B48,'Leads Pipeline'!$O$5:$O$1004,"Won"),"") | G48: =IF(AND($A48<>"",$B48<>""),SUMIFS('Leads Pipeline'!$U$5:$U$1004,'Leads Pipeline'!$D$5:$D$1004,$A48,'Leads Pipeline'!$E$5:$E$1004,$B48,'Leads Pipeline'!$O$5:$O$1004,"<>Won",'Leads Pipeline'!$O$5:$O$1004,"<>Lost"),"") | H48: =IF(AND($A48<>"",$B48<>""),COUNTIFS('Active Clients'!$B$5:$B$504,$A48,'Active Clients'!$C$5:$C$504,$B48,'Active Clients'!$T$5:$T$504,"Active"),"") | I48: =IF(AND($A48<>"",$B48<>""),SUMIFS('Active Clients'!$R$5:$R$504,'Active Clients'!$B$5:$B$504,$A48,'Active Clients'!$C$5:$C$504,$B48),"") | J48: =IF(AND($A48<>"",$B48<>""),COUNTIFS('Activity Log'!$E$5:$E$3004,$A48,'Activity Log'!$F$5:$F$3004,$B48,'Activity Log'!$A$5:$A$3004,">="&(TODAY()-29),'Activity Log'!$A$5:$A$3004,"<="&TODAY()),"")
C49: =IF(AND($A49<>"",$B49<>""),COUNTIFS('Leads Pipeline'!$D$5:$D$1004,$A49,'Leads Pipeline'!$E$5:$E$1004,$B49,'Leads Pipeline'!$F$5:$F$1004,"<>"),"") | D49: =IF(AND($A49<>"",$B49<>""),COUNTIFS('Leads Pipeline'!$D$5:$D$1004,$A49,'Leads Pipeline'!$E$5:$E$1004,$B49,'Leads Pipeline'!$F$5:$F$1004,"<>",'Leads Pipeline'!$O$5:$O$1004,"<>Won",'Leads Pipeline'!$O$5:$O$1004,"<>Lost"),"") | E49: =IF(AND($A49<>"",$B49<>""),COUNTIFS('Leads Pipeline'!$D$5:$D$1004,$A49,'Leads Pipeline'!$E$5:$E$1004,$B49,'Leads Pipeline'!$P$5:$P$1004,"Hot",'Leads Pipeline'!$O$5:$O$1004,"<>Won",'Leads Pipeline'!$O$5:$O$1004,"<>Lost"),"") | F49: =IF(AND($A49<>"",$B49<>""),COUNTIFS('Leads Pipeline'!$D$5:$D$1004,$A49,'Leads Pipeline'!$E$5:$E$1004,$B49,'Leads Pipeline'!$O$5:$O$1004,"Won"),"") | G49: =IF(AND($A49<>"",$B49<>""),SUMIFS('Leads Pipeline'!$U$5:$U$1004,'Leads Pipeline'!$D$5:$D$1004,$A49,'Leads Pipeline'!$E$5:$E$1004,$B49,'Leads Pipeline'!$O$5:$O$1004,"<>Won",'Leads Pipeline'!$O$5:$O$1004,"<>Lost"),"") | H49: =IF(AND($A49<>"",$B49<>""),COUNTIFS('Active Clients'!$B$5:$B$504,$A49,'Active Clients'!$C$5:$C$504,$B49,'Active Clients'!$T$5:$T$504,"Active"),"") | I49: =IF(AND($A49<>"",$B49<>""),SUMIFS('Active Clients'!$R$5:$R$504,'Active Clients'!$B$5:$B$504,$A49,'Active Clients'!$C$5:$C$504,$B49),"") | J49: =IF(AND($A49<>"",$B49<>""),COUNTIFS('Activity Log'!$E$5:$E$3004,$A49,'Activity Log'!$F$5:$F$3004,$B49,'Activity Log'!$A$5:$A$3004,">="&(TODAY()-29),'Activity Log'!$A$5:$A$3004,"<="&TODAY()),"")
C50: =IF(AND($A50<>"",$B50<>""),COUNTIFS('Leads Pipeline'!$D$5:$D$1004,$A50,'Leads Pipeline'!$E$5:$E$1004,$B50,'Leads Pipeline'!$F$5:$F$1004,"<>"),"") | D50: =IF(AND($A50<>"",$B50<>""),COUNTIFS('Leads Pipeline'!$D$5:$D$1004,$A50,'Leads Pipeline'!$E$5:$E$1004,$B50,'Leads Pipeline'!$F$5:$F$1004,"<>",'Leads Pipeline'!$O$5:$O$1004,"<>Won",'Leads Pipeline'!$O$5:$O$1004,"<>Lost"),"") | E50: =IF(AND($A50<>"",$B50<>""),COUNTIFS('Leads Pipeline'!$D$5:$D$1004,$A50,'Leads Pipeline'!$E$5:$E$1004,$B50,'Leads Pipeline'!$P$5:$P$1004,"Hot",'Leads Pipeline'!$O$5:$O$1004,"<>Won",'Leads Pipeline'!$O$5:$O$1004,"<>Lost"),"") | F50: =IF(AND($A50<>"",$B50<>""),COUNTIFS('Leads Pipeline'!$D$5:$D$1004,$A50,'Leads Pipeline'!$E$5:$E$1004,$B50,'Leads Pipeline'!$O$5:$O$1004,"Won"),"") | G50: =IF(AND($A50<>"",$B50<>""),SUMIFS('Leads Pipeline'!$U$5:$U$1004,'Leads Pipeline'!$D$5:$D$1004,$A50,'Leads Pipeline'!$E$5:$E$1004,$B50,'Leads Pipeline'!$O$5:$O$1004,"<>Won",'Leads Pipeline'!$O$5:$O$1004,"<>Lost"),"") | H50: =IF(AND($A50<>"",$B50<>""),COUNTIFS('Active Clients'!$B$5:$B$504,$A50,'Active Clients'!$C$5:$C$504,$B50,'Active Clients'!$T$5:$T$504,"Active"),"") | I50: =IF(AND($A50<>"",$B50<>""),SUMIFS('Active Clients'!$R$5:$R$504,'Active Clients'!$B$5:$B$504,$A50,'Active Clients'!$C$5:$C$504,$B50),"") | J50: =IF(AND($A50<>"",$B50<>""),COUNTIFS('Activity Log'!$E$5:$E$3004,$A50,'Activity Log'!$F$5:$F$3004,$B50,'Activity Log'!$A$5:$A$3004,">="&(TODAY()-29),'Activity Log'!$A$5:$A$3004,"<="&TODAY()),"")
C51: =IF(AND($A51<>"",$B51<>""),COUNTIFS('Leads Pipeline'!$D$5:$D$1004,$A51,'Leads Pipeline'!$E$5:$E$1004,$B51,'Leads Pipeline'!$F$5:$F$1004,"<>"),"") | D51: =IF(AND($A51<>"",$B51<>""),COUNTIFS('Leads Pipeline'!$D$5:$D$1004,$A51,'Leads Pipeline'!$E$5:$E$1004,$B51,'Leads Pipeline'!$F$5:$F$1004,"<>",'Leads Pipeline'!$O$5:$O$1004,"<>Won",'Leads Pipeline'!$O$5:$O$1004,"<>Lost"),"") | E51: =IF(AND($A51<>"",$B51<>""),COUNTIFS('Leads Pipeline'!$D$5:$D$1004,$A51,'Leads Pipeline'!$E$5:$E$1004,$B51,'Leads Pipeline'!$P$5:$P$1004,"Hot",'Leads Pipeline'!$O$5:$O$1004,"<>Won",'Leads Pipeline'!$O$5:$O$1004,"<>Lost"),"") | F51: =IF(AND($A51<>"",$B51<>""),COUNTIFS('Leads Pipeline'!$D$5:$D$1004,$A51,'Leads Pipeline'!$E$5:$E$1004,$B51,'Leads Pipeline'!$O$5:$O$1004,"Won"),"") | G51: =IF(AND($A51<>"",$B51<>""),SUMIFS('Leads Pipeline'!$U$5:$U$1004,'Leads Pipeline'!$D$5:$D$1004,$A51,'Leads Pipeline'!$E$5:$E$1004,$B51,'Leads Pipeline'!$O$5:$O$1004,"<>Won",'Leads Pipeline'!$O$5:$O$1004,"<>Lost"),"") | H51: =IF(AND($A51<>"",$B51<>""),COUNTIFS('Active Clients'!$B$5:$B$504,$A51,'Active Clients'!$C$5:$C$504,$B51,'Active Clients'!$T$5:$T$504,"Active"),"") | I51: =IF(AND($A51<>"",$B51<>""),SUMIFS('Active Clients'!$R$5:$R$504,'Active Clients'!$B$5:$B$504,$A51,'Active Clients'!$C$5:$C$504,$B51),"") | J51: =IF(AND($A51<>"",$B51<>""),COUNTIFS('Activity Log'!$E$5:$E$3004,$A51,'Activity Log'!$F$5:$F$3004,$B51,'Activity Log'!$A$5:$A$3004,">="&(TODAY()-29),'Activity Log'!$A$5:$A$3004,"<="&TODAY()),"")
C52: =IF(AND($A52<>"",$B52<>""),COUNTIFS('Leads Pipeline'!$D$5:$D$1004,$A52,'Leads Pipeline'!$E$5:$E$1004,$B52,'Leads Pipeline'!$F$5:$F$1004,"<>"),"") | D52: =IF(AND($A52<>"",$B52<>""),COUNTIFS('Leads Pipeline'!$D$5:$D$1004,$A52,'Leads Pipeline'!$E$5:$E$1004,$B52,'Leads Pipeline'!$F$5:$F$1004,"<>",'Leads Pipeline'!$O$5:$O$1004,"<>Won",'Leads Pipeline'!$O$5:$O$1004,"<>Lost"),"") | E52: =IF(AND($A52<>"",$B52<>""),COUNTIFS('Leads Pipeline'!$D$5:$D$1004,$A52,'Leads Pipeline'!$E$5:$E$1004,$B52,'Leads Pipeline'!$P$5:$P$1004,"Hot",'Leads Pipeline'!$O$5:$O$1004,"<>Won",'Leads Pipeline'!$O$5:$O$1004,"<>Lost"),"") | F52: =IF(AND($A52<>"",$B52<>""),COUNTIFS('Leads Pipeline'!$D$5:$D$1004,$A52,'Leads Pipeline'!$E$5:$E$1004,$B52,'Leads Pipeline'!$O$5:$O$1004,"Won"),"") | G52: =IF(AND($A52<>"",$B52<>""),SUMIFS('Leads Pipeline'!$U$5:$U$1004,'Leads Pipeline'!$D$5:$D$1004,$A52,'Leads Pipeline'!$E$5:$E$1004,$B52,'Leads Pipeline'!$O$5:$O$1004,"<>Won",'Leads Pipeline'!$O$5:$O$1004,"<>Lost"),"") | H52: =IF(AND($A52<>"",$B52<>""),COUNTIFS('Active Clients'!$B$5:$B$504,$A52,'Active Clients'!$C$5:$C$504,$B52,'Active Clients'!$T$5:$T$504,"Active"),"") | I52: =IF(AND($A52<>"",$B52<>""),SUMIFS('Active Clients'!$R$5:$R$504,'Active Clients'!$B$5:$B$504,$A52,'Active Clients'!$C$5:$C$504,$B52),"") | J52: =IF(AND($A52<>"",$B52<>""),COUNTIFS('Activity Log'!$E$5:$E$3004,$A52,'Activity Log'!$F$5:$F$3004,$B52,'Activity Log'!$A$5:$A$3004,">="&(TODAY()-29),'Activity Log'!$A$5:$A$3004,"<="&TODAY()),"")
